Workbook

Sheet Ordre d'exécution
A1: Backlog GestionProjet — ordre d'exécution
A2: Généré le 16/10/2026 14:45 depuis backlog/BACKLOG.md. Ne pas modifier : les statuts changent via /lancer-phase, /valider-phase, /refuser-tache et scripts/backlog.py.
A4: Phase | B4: Titre | C4: Statut phase | D4: Modèle conseillé | E4: Tâches | F4: Faites | G4: Avancement | H4: Bloquées
A5: P0 | B5: Initialisation et outillage | C5: VALIDEE | D5: sonnet | E5: =COUNTA('P0'!B8:B200) | F5: =COUNTIF('P0'!F8:F200,"A_VALIDER")+COUNTIF('P0'!F8:F200,"VALIDE") | G5: =IF(E5=0,0,F5/E5) | H5: =COUNTIF('P0'!F8:F200,"BLOQUE")
A6: P1 | B6: Socle backend .NET 10 | C6: EN_COURS | D6: opus | E6: =COUNTA('P1'!B8:B200) | F6: =COUNTIF('P1'!F8:F200,"A_VALIDER")+COUNTIF('P1'!F8:F200,"VALIDE") | G6: =IF(E6=0,0,F6/E6) | H6: =COUNTIF('P1'!F8:F200,"BLOQUE")
A7: P2 | B7: Socle frontend Blazor WebAssembly et BFF | C7: NON_DEMARREE | D7: sonnet | E7: =COUNTA('P2'!B8:B200) | F7: =COUNTIF('P2'!F8:F200,"A_VALIDER")+COUNTIF('P2'!F8:F200,"VALIDE") | G7: =IF(E7=0,0,F7/E7) | H7: =COUNTIF('P2'!F8:F200,"BLOQUE")
A8: P3 | B8: Conteneurisation et intégration continue GitHub Actions | C8: NON_DEMARREE | D8: sonnet | E8: =COUNTA('P3'!B8:B200) | F8: =COUNTIF('P3'!F8:F200,"A_VALIDER")+COUNTIF('P3'!F8:F200,"VALIDE") | G8: =IF(E8=0,0,F8/E8) | H8: =COUNTIF('P3'!F8:F200,"BLOQUE")
A9: P4 | B9: Module Organisation et périmètre hiérarchique | C9: NON_DEMARREE | D9: sonnet | E9: =COUNTA('P4'!B8:B200) | F9: =COUNTIF('P4'!F8:F200,"A_VALIDER")+COUNTIF('P4'!F8:F200,"VALIDE") | G9: =IF(E9=0,0,F9/E9) | H9: =COUNTIF('P4'!F8:F200,"BLOQUE")
A10: P5 | B10: Projets et affectation en cascade | C10: NON_DEMARREE | D10: opus | E10: =COUNTA('P5'!B8:B200) | F10: =COUNTIF('P5'!F8:F200,"A_VALIDER")+COUNTIF('P5'!F8:F200,"VALIDE") | G10: =IF(E10=0,0,F10/E10) | H10: =COUNTIF('P5'!F8:F200,"BLOQUE")
A11: P6 | B11: Planification et ordonnancement | C11: NON_DEMARREE | D11: opus | E11: =COUNTA('P6'!B8:B200) | F11: =COUNTIF('P6'!F8:F200,"A_VALIDER")+COUNTIF('P6'!F8:F200,"VALIDE") | G11: =IF(E11=0,0,F11/E11) | H11: =COUNTIF('P6'!F8:F200,"BLOQUE")
A12: P7 | B12: Coût en temps | C12: NON_DEMARREE | D12: sonnet | E12: =COUNTA('P7'!B8:B200) | F12: =COUNTIF('P7'!F8:F200,"A_VALIDER")+COUNTIF('P7'!F8:F200,"VALIDE") | G12: =IF(E12=0,0,F12/E12) | H12: =COUNTIF('P7'!F8:F200,"BLOQUE")
A13: P8 | B13: Reporting par niveau hiérarchique | C13: NON_DEMARREE | D13: sonnet | E13: =COUNTA('P8'!B8:B200) | F13: =COUNTIF('P8'!F8:F200,"A_VALIDER")+COUNTIF('P8'!F8:F200,"VALIDE") | G13: =IF(E13=0,0,F13/E13) | H13: =COUNTIF('P8'!F8:F200,"BLOQUE")
A14: P9 | B14: Collaboration et services transverses | C14: NON_DEMARREE | D14: sonnet | E14: =COUNTA('P9'!B8:B200) | F14: =COUNTIF('P9'!F8:F200,"A_VALIDER")+COUNTIF('P9'!F8:F200,"VALIDE") | G14: =IF(E14=0,0,F14/E14) | H14: =COUNTIF('P9'!F8:F200,"BLOQUE")
A15: P10 | B15: Modélisation et diagrammes | C15: NON_DEMARREE | D15: opus | E15: =COUNTA('P10'!B8:B200) | F15: =COUNTIF('P10'!F8:F200,"A_VALIDER")+COUNTIF('P10'!F8:F200,"VALIDE") | G15: =IF(E15=0,0,F15/E15) | H15: =COUNTIF('P10'!F8:F200,"BLOQUE")
A16: P11 | B16: Générateur de code | C16: NON_DEMARREE | D16: opus | E16: =COUNTA('P11'!B8:B200) | F16: =COUNTIF('P11'!F8:F200,"A_VALIDER")+COUNTIF('P11'!F8:F200,"VALIDE") | G16: =IF(E16=0,0,F16/E16) | H16: =COUNTIF('P11'!F8:F200,"BLOQUE")
A17: P12 | B17: Intégration GitLab | C17: NON_DEMARREE | D17: sonnet | E17: =COUNTA('P12'!B8:B200) | F17: =COUNTIF('P12'!F8:F200,"A_VALIDER")+COUNTIF('P12'!F8:F200,"VALIDE") | G17: =IF(E17=0,0,F17/E17) | H17: =COUNTIF('P12'!F8:F200,"BLOQUE")
A18: P13 | B18: Déploiement Docker | C18: NON_DEMARREE | D18: sonnet | E18: =COUNTA('P13'!B8:B200) | F18: =COUNTIF('P13'!F8:F200,"A_VALIDER")+COUNTIF('P13'!F8:F200,"VALIDE") | G18: =IF(E18=0,0,F18/E18) | H18: =COUNTIF('P13'!F8:F200,"BLOQUE")
A19: P14 | B19: Cadrage, exigences et conception des écrans | C19: NON_DEMARREE | D19: sonnet | E19: =COUNTA('P14'!B8:B200) | F19: =COUNTIF('P14'!F8:F200,"A_VALIDER")+COUNTIF('P14'!F8:F200,"VALIDE") | G19: =IF(E19=0,0,F19/E19) | H19: =COUNTIF('P14'!F8:F200,"BLOQUE")
A20: P15 | B20: Qualité, recette et DevSecOps | C20: NON_DEMARREE | D20: sonnet | E20: =COUNTA('P15'!B8:B200) | F20: =COUNTIF('P15'!F8:F200,"A_VALIDER")+COUNTIF('P15'!F8:F200,"VALIDE") | G20: =IF(E20=0,0,F20/E20) | H20: =COUNTIF('P15'!F8:F200,"BLOQUE")
A21: P16 | B21: Documentation, méthodes agiles, automatisation et API | C21: NON_DEMARREE | D21: sonnet | E21: =COUNTA('P16'!B8:B200) | F21: =COUNTIF('P16'!F8:F200,"A_VALIDER")+COUNTIF('P16'!F8:F200,"VALIDE") | G21: =IF(E21=0,0,F21/E21) | H21: =COUNTIF('P16'!F8:F200,"BLOQUE")
A22: P17 | B22: Expérience utilisateur transverse et accessibilité | C22: NON_DEMARREE | D22: sonnet | E22: =COUNTA('P17'!B8:B200) | F22: =COUNTIF('P17'!F8:F200,"A_VALIDER")+COUNTIF('P17'!F8:F200,"VALIDE") | G22: =IF(E22=0,0,F22/E22) | H22: =COUNTIF('P17'!F8:F200,"BLOQUE")
A23: P18 | B23: Sécurité Keycloak et durcissement | C23: NON_DEMARREE | D23: opus | E23: =COUNTA('P18'!B8:B200) | F23: =COUNTIF('P18'!F8:F200,"A_VALIDER")+COUNTIF('P18'!F8:F200,"VALIDE") | G23: =IF(E23=0,0,F23/E23) | H23: =COUNTIF('P18'!F8:F200,"BLOQUE")
A24: P19 | B24: Performance, recette finale et mise en production | C24: NON_DEMARREE | D24: sonnet | E24: =COUNTA('P19'!B8:B200) | F24: =COUNTIF('P19'!F8:F200,"A_VALIDER")+COUNTIF('P19'!F8:F200,"VALIDE") | G24: =IF(E24=0,0,F24/E24) | H24: =COUNTIF('P19'!F8:F200,"BLOQUE")
B25: Total | E25: =SUM(E5:E24) | F25: =SUM(F5:F24) | G25: =IF(E25=0,0,F25/E25) | H25: =SUM(H5:H24)
A27: Séquence d'exécution des tâches
A28: N° | B28: Phase | C28: Code | D28: Tâche | E28: Modèle | F28: Ordre | G28: Dépend de | H28: Statut | I28: Hypothèses
A29: 1 | B29: P0 · Initialisation et outillage | C29: P0-T01 | D29: Initialiser le dépôt Git et la branche de phase | E29: haiku | F29: 1 | G29: — | H29: VALIDE
A30: 2 | B30: P0 · Initialisation et outillage | C30: P0-T02 | D30: Script de vérification de l'environnement | E30: haiku | F30: 2 | G30: P0-T01 | H30: VALIDE | I30: H-015
A31: 3 | B31: P0 · Initialisation et outillage | C31: P0-T03 | D31: Valider l'instance PostgreSQL de test et le schéma de référence | E31: sonnet | F31: 3 | G31: P0-T01 | H31: VALIDE | I31: H-016
A32: 4 | B32: P0 · Initialisation et outillage | C32: P0-T04 | D32: Conventions de build .NET centralisées | E32: haiku | F32: 4 | G32: P0-T01 | H32: VALIDE | I32: H-017
A33: 5 | B33: P0 · Initialisation et outillage | C33: P0-T05 | D33: Modèles GitLab et guide de contribution | E33: haiku | F33: 5 | G33: P0-T01 | H33: VALIDE
A34: 6 | B34: P0 · Initialisation et outillage | C34: P0-T06 | D34: Rapport d'outillage Claude Code | E34: haiku | F34: 6 | G34: P0-T02 | H34: VALIDE | I34: H-003, H-018
A35: 7 | B35: P1 · Socle backend .NET 10 | C35: P1-T01 | D35: Créer la solution et le projet Gprojet-Backend | E35: sonnet | F35: 1 | G35: — | H35: A_VALIDER
A36: 8 | B36: P1 · Socle backend .NET 10 | C36: P1-T02 | D36: Tests d'architecture par espace de noms | E36: opus | F36: 2 | G36: P1-T01 | H36: A_VALIDER | I36: H-019
A37: 9 | B37: P1 · Socle backend .NET 10 | C37: P1-T03 | D37: Common : primitives transverses | E37: sonnet | F37: 3 | G37: P1-T01 | H37: A_VALIDER | I37: H-020
A38: 10 | B38: P1 · Socle backend .NET 10 | C38: P1-T04 | D38: Entités du domaine (6 schémas) | E38: opus | F38: 4 | G38: P1-T03 | H38: A_VALIDER | I38: H-021
A39: 11 | B39: P1 · Socle backend .NET 10 | C39: P1-T05 | D39: DbContext et configurations EF Core | E39: opus | F39: 5 | G39: P1-T04 | H39: A_VALIDER | I39: H-022
A40: 12 | B40: P1 · Socle backend .NET 10 | C40: P1-T06 | D40: Migration initiale identique au schéma de référence | E40: opus | F40: 6 | G40: P1-T05 | H40: EN_COURS | I40: H-023
A41: 13 | B41: P1 · Socle backend .NET 10 | C41: P1-T07 | D41: Intercepteurs : audit, suppression logique, historique chaîné | E41: sonnet | F41: 7 | G41: P1-T06 | H41: NON_FAIT
A42: 14 | B42: P1 · Socle backend .NET 10 | C42: P1-T08 | D42: Unit of Work et repositories de base | E42: sonnet | F42: 8 | G42: P1-T06 | H42: NON_FAIT
...

Sheet P0
A1: P0 · Initialisation et outillage
A2: Objectif : dépôt Git propre, conventions, environnement vérifié, base de test opérationnelle. Livrable : un dépôt prêt à recevoir la solution .NET.
A3: Statut phase | B3: VALIDEE
A4: Modèle conseillé | B4: sonnet
A5: Avancement | B5: =IF(COUNTA(B8:B200)=0,0,(COUNTIF(F8:F200,"A_VALIDER")+COUNTIF(F8:F200,"VALIDE"))/COUNTA(B8:B200))
A6: ← Retour à l'ordre d'exécution
A7: Ordre | B7: Code | C7: Tâche | D7: Modèle | E7: Dépend de | F7: Statut | G7: Explication | H7: Test de validation | I7: Retours utilisateur | J7: Hypothèses liées
A8: 1 | B8: P0-T01 | C8: Initialiser le dépôt Git et la branche de phase | D8: haiku | E8: — | F8: VALIDE | G8: git init -b main à la racine du projet, premier commit contenant l'existant (CLAUDE.md, .claude/, backlog/, scripts/, database/), puis branche phase/P0-initialisation. Le .gitignore existe déjà (secrets locaux dont .claude/settings.local.json, .pgtest/, .NET) : le vérifier avant le premier git add, le compléter si besoin. Créer .gitattributes (* text=auto eol=lf, *.sql et *.md en LF, *.ps1 en CRLF). | H8: git log --oneline montre au moins 2 commits ; git status --porcelain est vide ; git check-ignore .pgtest/x bin/x .claude/settings.local.json renvoie les trois chemins ; git ls-files | grep -c settings.local renvoie 0.
A9: 2 | B9: P0-T02 | C9: Script de vérification de l'environnement | D9: haiku | E9: P0-T01 | F9: VALIDE | G9: scripts/verifier-env.py affiche un tableau OK / MANQUANT / OPTIONNEL pour : .NET SDK 10, Python ≥ 3.12 avec le module openpyxl (export Excel du backlog), binaires PostgreSQL 18 (PG_BIN), Git, Node.js (optionnel : ponytail, motion), Docker (requis à partir de P3), uv et graphify (optionnels). Code de sortie 1 si un outil requis manque. | H9: python scripts/verifier-env.py affiche le tableau et sort en 0 sur ce poste (dotnet, python, PostgreSQL, git présents) ; en masquant PG_BIN vers un dossier vide, il sort en 1. | J9: H-015 (OUVERTE)
A10: 3 | B10: P0-T03 | C10: Valider l'instance PostgreSQL de test et le schéma de référence | D10: sonnet | E10: P0-T01 | F10: VALIDE | G10: utiliser scripts/pg-test.py pour démarrer l'instance jetable, appliquer database/01 et 02, exécuter database/03-tests-integrite.sql, puis arrêter. Ajouter scripts/tester-schema.py qui automatise cela et vérifie que les 13 blocs « attendu ERREUR » échouent et que les autres réussissent (analyse de la sortie psql). | H10: python scripts/tester-schema.py sort en 0 et affiche « 18/18 vérifications conformes » ; .pgtest/ n'existe plus après exécution. | J10: H-016 (OUVERTE)
A11: 4 | B11: P0-T04 | C11: Conventions de build .NET centralisées | D11: haiku | E11: P0-T01 | F11: VALIDE | G11: global.json (SDK 10.0.4xx, rollForward: latestFeature), Directory.Build.props (net10.0, Nullable enable, ImplicitUsings enable, TreatWarningsAsErrors true, AnalysisLevel latest-recommended, InvariantGlobalization false), Directory.Packages.props (gestion centralisée des versions : EF Core 10, Npgsql 10, Mapperly, FluentValidation, Serilog, xUnit, FluentAssertions, bUnit, NetArchTest, Microsoft.AspNetCore.Components.WebAssembly et .Server), .editorconfig (style C# : file-scoped namespaces, var si évident, accolades, nommage _champ). | H11: dotnet --version (dans le dossier) renvoie une version 10.0.4xx ; dotnet new console -o .tmpcheck && dotnet build .tmpcheck réussit avec les props appliquées (vérifier TreatWarningsAsErrors dans obj/*.nuget.g.props ou via dotnet msbuild -getProperty:TreatWarningsAsErrors) ; supprimer .tmpcheck. | J11: H-017 (REPONDUE)
A12: 5 | B12: P0-T05 | C12: Modèles GitLab et guide de contribution | D12: haiku | E12: P0-T01 | F12: VALIDE | G12: .gitlab/merge_request_templates/Phase.md (résumé de phase, tâches, preuves, hypothèses, checklist de revue), .gitlab/issue_templates/Anomalie.md et Demande.md, CONTRIBUTING.md (branches phase/Pn-…, commits Pn-Tnn: …, revue, règles des couches, comment lancer les tests). | H12: les 4 fichiers existent ; CONTRIBUTING.md contient les sections « Branches », « Commits », « Architecture », « Tests » (grep -c "^## " ≥ 4).
A13: 6 | B13: P0-T06 | C13: Rapport d'outillage Claude Code | D13: haiku | E13: P0-T02 | F13: VALIDE | G13: docs/OUTILLAGE.md : état réel des plugins / skills (graphify, ponytail, ui-ux-pro-max, motion-design) détecté sur le poste (~/.claude/skills, .claude/skills, ~/.claude/plugins), des hooks et des sous-agents du projet, avec la commande d'installation de chaque élément manquant (voir scripts/installer-outils.ps1). Si un outil manque, créer une hypothèse non bloquante. | H13: docs/OUTILLAGE.md liste les 4 outils avec un statut chacun ; python scripts/backlog.py contexte s'exécute sans erreur. | J13: H-003 (REPONDUE) H-018 (OUVERTE)

Sheet P1
A1: P1 · Socle backend .NET 10
A2: Objectif : solution en couches compilable, persistance PostgreSQL identique au schéma de référence, API démarrable. Livrable : Gprojet.slnx avec le projet unique Gprojet-Backend + API /health + tests d'architecture verts.
A3: Statut phase | B3: EN_COURS
A4: Modèle conseillé | B4: opus
A5: Avancement | B5: =IF(COUNTA(B8:B200)=0,0,(COUNTIF(F8:F200,"A_VALIDER")+COUNTIF(F8:F200,"VALIDE"))/COUNTA(B8:B200))
A6: ← Retour à l'ordre d'exécution
A7: Ordre | B7: Code | C7: Tâche | D7: Modèle | E7: Dépend de | F7: Statut | G7: Explication | H7: Test de validation | I7: Retours utilisateur | J7: Hypothèses liées
A8: 1 | B8: P1-T01 | C8: Créer la solution et le projet Gprojet-Backend | D8: sonnet | E8: — | F8: A_VALIDER | G8: Gprojet.slnx ; un seul projet backend src/Gprojet-Backend/Gprojet-Backend.csproj (Microsoft.NET.Sdk.Web, RootNamespace Gprojet.Backend) avec les dossiers-couches Web/, Orchestration/, Services/, Mapping/, Repositories/, Entities/, Contracts/, Infrastructure/, Common/ (espaces de noms alignés sur les dossiers) ; projet de tests tests/Gprojet-Backend.Tests (xUnit) avec Unitaires/, Integration/, Architecture/. Aucun autre projet (le front arrive en P2-T01). Demandes utilisateur à intégrer dans cette tâche : Directory.Packages.props → FluentAssertions en dernière 7.x stable (licence Apache 2.0, H-017) au lieu de 8.x ; migrer .gitlab/ vers .github/ (pull_request_template.md, ISSUE_TEMPLATE/Anomalie.md et Demande.md) et adapter CONTRIBUTING.md (pull requests GitHub). | H8: dotnet build Gprojet.slnx réussit sans avertissement ; dotnet sln Gprojet.slnx list affiche exactement 2 projets (Gprojet-Backend, Gprojet-Backend.Tests) ; dotnet test passe (test de fumée). Directory.Packages.props référence FluentAssertions 7.x ; .gitlab/ n'existe plus et .github/pull_request_template.md existe.
A9: 2 | B9: P1-T02 | C9: Tests d'architecture par espace de noms | D9: opus | E9: P1-T01 | F9: A_VALIDER | G9: les couches étant des dossiers d'un même projet, ces tests remplacent le compilateur comme garde. NetArchTest dans tests/Gprojet-Backend.Tests/Architecture/, une règle par interdiction entre espaces de noms Gprojet.Backend.* : Web ↛ Services / Repositories / Entities ; Orchestration ↛ implémentations de Repositories ; Services ↛ Contracts, Mapping, EF Core ; Entities ↛ toute autre couche sauf Common ; Contracts ↛ tout sauf BCL et FluentValidation (compilé dans le navigateur) ; types *Dto uniquement dans Contracts ; contrôleurs uniquement dans Web. Test « garde-fou » : des types de violation volontaire, définis dans le projet de test sous des espaces de noms simulés, sont bien détectés. | H9: dotnet test tests/Gprojet-Backend.Tests --filter Category=Architecture → tous verts, ≥ 10 règles ; le garde-fou prouve qu'une violation fait échouer la règle (assert inversé). | J9: H-019 (OUVERTE)
A10: 3 | B10: P1-T03 | C10: Common : primitives transverses | D10: sonnet | E10: P1-T01 | F10: A_VALIDER | G10: Result<T> / Result, exceptions métier (RegleMetierException, AccesRefuseException, IntrouvableException, ConflitException), PageRequete / PageResultat<T> (tri, filtre, taille max 200), ICurrentUser (Id agent, matricule, entité, rôles), IHorloge (testable), IGenerateurCode (codes lisibles). | H10: dotnet test tests/Gprojet-Backend.Tests --filter Category=Common → tests de Result, pagination (bornes, taille max) et horloge factice verts. | J10: H-020 (OUVERTE)
A11: 4 | B11: P1-T04 | C11: Entités du domaine (6 schémas) | D11: opus | E11: P1-T03 | F11: A_VALIDER | G11: EntiteAuditable (Id Guid v7, audit, suppression logique) et une classe par table de database/01-schema.sql, rangées par module (Organisation, Projets, Planification, Temps, Commun, Modelisation), avec propriétés de navigation, collections, et énumérations C# pour chaque CHECK … IN. Historique n'hérite pas d'EntiteAuditable (bigint, ajout seul). | H11: dotnet build OK ; test de réflexion : nombre de types entités = 60 et chaque énumération a les mêmes valeurs que la contrainte SQL correspondante (test paramétré lisant 01-schema.sql). | J11: H-021 (OUVERTE)
A12: 5 | B12: P1-T05 | C12: DbContext et configurations EF Core | D12: opus | E12: P1-T04 | F12: A_VALIDER | G12: GpDbContext (Npgsql, extension ltree), une IEntityTypeConfiguration<T> par entité : schéma, noms snake_case, types (numeric(p,s), ltree, jsonb, text[], inet), uuidv7() par défaut, contraintes CHECK, index uniques partiels (HasFilter), index GiST, colonne générée criticite, xmin (concurrence), filtre global !EstSupprime, conversions enum → texte. | H12: dotnet build OK ; dotnet ef dbcontext info réussit ; test unitaire : le modèle EF déclare 60 tables réparties dans les 6 schémas. | J12: H-022 (OUVERTE)
A13: 6 | B13: P1-T06 | C13: Migration initiale identique au schéma de référence | D13: opus | E13: P1-T05 | F13: EN_COURS | G13: migration InitialCreate (+ trigger d'ajout seul sur commun.historique et données de 02-donnees-reference.sql via migrationBuilder.Sql). Écrire scripts/comparer-schema.py : crée deux bases sur l'instance de test (l'une par 01-schema.sql, l'autre par dotnet ef database update), puis compare colonnes (type, nullabilité, défaut), contraintes, index (définition) et triggers via pg_catalog. Appliquer ensuite la migration à la base de développement gprojet (vide au départ ; connexion fournie par la variable ConnectionStrings__Gp, définie dans .claude/settings.local.json — ne jamais l'afficher ni la recopier). | H13: python scripts/comparer-schema.py → « 0 écart » ; toute différence est listée et fait échouer le script ; dotnet ef database update sur gprojet réussit et gprojet contient 60 tables dans les 6 schémas. | J13: H-023 (OUVERTE)
A14: 7 | B14: P1-T07 | C14: Intercepteurs : audit, suppression logique, historique chaîné | D14: sonnet | E14: P1-T06 | F14: NON_FAIT | G14: SaveChangesInterceptor qui renseigne cree_* / modifie_* depuis ICurrentUser et IHorloge, transforme un Remove en suppression logique, et écrit une ligne commun.historique par champ modifié avec l'empreinte sha256(empreinte_precedente + contenu) et un correlation_id par requête. | H14: tests d'intégration sur pg-test : création → audit rempli ; suppression → est_supprime = true et ligne invisible via le filtre global ; modification → lignes d'historique avec chaîne d'empreintes valide (recalcul) ; altérer une ligne en SQL direct est détecté par le vérificateur de chaîne.
A15: 8 | B15: P1-T08 | C15: Unit of Work et repositories de base | D15: sonnet | E15: P1-T06 | F15: NON_FAIT | G15: IUnitOfWork (CommitAsync, transaction explicite), classe de base interne RepositoryBase<T> (GetById, Ajouter, Supprimer logique, pagination), interfaces de repository par agrégat dans Repositories/ (exposées via des interfaces consommées par les Services). Gestion de DbUpdateConcurrencyException → ConflitException. | H15: tests d'intégration : commit atomique (échec au milieu → rien n'est écrit) ; deux mises à jour concurrentes de la même ligne → ConflitException.
A16: 9 | B16: P1-T09 | C16: Socle API : DI, erreurs, OpenAPI, logs, santé | D16: sonnet | E16: P1-T08 | F16: NON_FAIT | G16: Program.cs minimal ; méthodes d'extension d'enregistrement par couche (AddGpRepositories, AddGpServices, AddGpOrchestration…) ; middleware d'exceptions → ProblemDetails (400/403/404/409/500 sans fuite de détail en production) ; OpenAPI natif + Scalar en Development ; Serilog (console JSON) ; /health (live) et /health/ready (base) ; chaîne de connexion via configuration (ConnectionStrings:Gp), fournie en local par la variable d'environnement ConnectionStrings__Gp (base gprojet, définie dans .claude/settings.local.json) ; les tests n'utilisent jamais gprojet : instance jetable pg-test ou GP_TEST_CONNECTION, qui écrasent explicitement cette valeur. | H16: test d'intégration WebApplicationFactory : /health 200, /health/ready 200 sur pg-test, /openapi/v1.json 200, une IntrouvableException levée par un contrôleur de test → 404 au format application/problem+json ; dotnet run de l'API puis curl -s localhost:<port>/health/ready → 200 sur gprojet. | J16: H-004 (REPONDUE)
A17: 10 | B17: P1-T10 | C17: Authentification de développement et utilisateur courant | D17: sonnet | E17: P1-T09 | F17: NON_FAIT | G17: DevAuthHandler (schéma « Dev », actif uniquement en environnement Development/Test) qui lit l'en-tête X-Dev-Matricule, charge l'agent et ses rôles déduits (responsable d'entité, délégation active) ; implémentation ICurrentUser. Keycloak le remplacera en P18. | H17: tests d'intégration : sans en-tête → 401 ; matricule inconnu → 401 ; matricule valide → 200 et ICurrentUser renseigné ; en environnement Production le schéma « Dev » n'est pas enregistré.
A18: 11 | B18: P1-T11 | C18: Données de démonstration | D18: haiku | E18: P1-T06 | F18: NON_FAIT | G18: database/04-donnees-demo.sql : 1 direction, 3 divisions, 6 services, 25 agents fictifs (responsables nommés, fonctions, compétences), 2 délégations, quelques absences, jours fériés de l'année. Uniquement des noms fictifs. Option --demo dans pg-test.py demarrer. | H18: python scripts/pg-test.py demarrer --demo puis requêtes de comptage : 10 entités, 25 agents, 10 responsables ; chaque service a un parent division (requête ltree).

Sheet P2
A1: P2 · Socle frontend Blazor WebAssembly et BFF
A2: Objectif : projet unique Gprojet-Front servi par Gprojet-Backend (BFF intégré), charte et layout définitifs, couches front en place. Livrable : coquille navigable authentifiée (auth de dev).
A3: Statut phase | B3: NON_DEMARREE
A4: Modèle conseillé | B4: sonnet
A5: Avancement | B5: =IF(COUNTA(B8:B200)=0,0,(COUNTIF(F8:F200,"A_VALIDER")+COUNTIF(F8:F200,"VALIDE"))/COUNTA(B8:B200))
A6: ← Retour à l'ordre d'exécution
A7: Ordre | B7: Code | C7: Tâche | D7: Modèle | E7: Dépend de | F7: Statut | G7: Explication | H7: Test de validation | I7: Retours utilisateur | J7: Hypothèses liées
A8: 1 | B8: P2-T01 | C8: Projet Gprojet-Front, hébergement par le backend et tests bUnit | D8: sonnet | E8: — | F8: NON_FAIT | G8: un seul projet front src/Gprojet-Front/Gprojet-Front.csproj (Microsoft.NET.Sdk.BlazorWebAssembly, RootNamespace Gprojet.Front) ; les DTO y sont des fichiers liés (<Compile Include="..\Gprojet-Backend\Contracts\\*.cs" Link="Contracts\%(RecursiveDir)%(Filename)%(Extension)" />), jamais copiés ; Gprojet-Backend référence Gprojet-Front et le sert (UseBlazorFrameworkFiles, MapFallbackToFile("index.html"), paquet Microsoft.AspNetCore.Components.WebAssembly.Server) : même origine, pas de proxy ni de CORS ; tests tests/Gprojet-Front.Tests (bUnit). Arborescence des couches front : Api/, Services/, Models/, Pages/, Components/, Layouts/, State/, Auth/, Resources/, wwwroot/css/, wwwroot/fonts/, wwwroot/lib/, wwwroot/images/. | H8: dotnet build Gprojet.slnx OK et dotnet sln list affiche exactement 4 projets ; test d'intégration backend : GET / → 200 HTML contenant blazor.webassembly, GET /api/health → 200 ; un DTO de Gprojet-Backend/Contracts est utilisé dans le front (compilation) ; règle d'architecture : le front ne référence aucun autre code du backend.
A9: 2 | B9: P2-T02 | C9: Charte HCP : intégration de app.css et des ressources | D9: sonnet | E9: P2-T01 | F9: NON_FAIT | G9: appliquer design/charte-hcp/README.md. Copier design/charte-hcp/app.css dans wwwroot/css/app.css sans autre modification que le remplacement de l'@import Google Fonts par un @font-face local (Geist, licence OFL, fichiers dans wwwroot/fonts/). Créer wwwroot/css/app.gp.css (chargé après) : variantes de texte accessibles (--success-text, --warning-text, --danger-text, --info-text, --purple-text), badges des statuts GestionProjet (.status-badge.a-faire, .a-valider, .bloque, .valide…), classes manquantes, le tout à partir des variables de la charte. Auto-héberger Font Awesome Free 6 et Chart.js dans wwwroot/lib/ ; logo HCP dans wwwroot/images/. docs/DESIGN.md : renvoi vers la charte et inventaire des classes utilisées / ajoutées. | H9: un script compare design/charte-hcp/app.css et wwwroot/css/app.css : seule la ligne @import diffère ; grep -rE "https?://" src/Gprojet-Front/wwwroot/index.html src/Gprojet-Front/wwwroot/css ne renvoie rien (aucune ressource externe) ; aucune couleur hexadécimale dans Pages/, Components/, Layouts/ ni dans app.gp.css hors des 5 variables de texte documentées ; contraste de chaque variable de texte ≥ 4,5:1 (calcul dans un test). | J9: H-014 (REPONDUE)
A10: 3 | B10: P2-T03 | C10: Layout principal et navigation par rôle | D10: sonnet | E10: P2-T02 | F10: NON_FAIT | G10: MainLayout identique à celui de la GED HCP : .page > aside.sidebar (.sidebar-brand avec logo HCP, sections .nav-section-label, .nav-item avec icône et .nav-badge, pied .user-row) + .main-area > .topbar (bouton de repli, .breadcrumb-nav, .search-box avec raccourci Ctrl+K, notifications) + .content-area. Menu construit selon les rôles / politiques (AuthorizeView) ; repli du menu et mode mobile (classes sidebar-collapsed, mobile-open dans app.gp.css). | H10: tests bUnit : le rendu contient .page .sidebar, .main-area .topbar et .content-area ; un agent ne voit pas l'entrée « Portefeuille direction », un directeur la voit ; l'action de repli ajoute sidebar-collapsed.
A11: 4 | B11: P2-T04 | C11: Mouvement selon la charte (motion-design) | D11: sonnet | E11: P2-T02 | F11: NON_FAIT | G11: réutiliser uniquement les mouvements de la charte (0.15s ease pour les survols, fadeIn 0.25s / .animate-in pour les apparitions, 0.6s pour les barres de progression) ; motion-design sert à décider où les appliquer (apparition des pages et des listes, dialogues, repli du menu), pas à créer d'autres durées. Neutralisation complète sous prefers-reduced-motion: reduce dans app.gp.css. Documenter dans docs/DESIGN.md. | H11: app.gp.css contient un bloc @media (prefers-reduced-motion: reduce) qui neutralise transition et animation ; aucune durée autre que 0.1s, 0.15s, 0.25s, 0.6s dans les CSS du projet (grep) ; aucune bibliothèque JS d'animation ajoutée (git diff --stat sur wwwroot/lib vide).
A12: 5 | B12: P2-T05 | C12: Couche Api : clients HTTP typés | D12: sonnet | E12: P2-T01 | F12: NON_FAIT | G12: ApiClientBase (sérialisation System.Text.Json, conversion ProblemDetails → ApiException typée avec erreurs de validation, annulation), enregistrement des clients via IHttpClientFactory en adresses relatives (même origine que le backend), premier client SanteApiClient. | H12: tests unitaires avec HttpMessageHandler simulé : 200 → DTO ; 400 problem+json → ApiException contenant les erreurs par champ ; 404 → ApiException.Statut == 404.
A13: 6 | B13: P2-T06 | C13: Authentification côté front (BFF, mode dev) | D13: sonnet | E13: P2-T05 | F13: NON_FAIT | G13: endpoints BFF dans Gprojet-Backend/Web/Auth/ : /bff/login (dev : choix d'un matricule de démo), /bff/logout, /bff/user ; cookie HttpOnly, Secure, SameSite=Strict ; jeton anti-CSRF exigé sur les appels mutants ; BffAuthenticationStateProvider côté WASM ; page de connexion de développement. | H13: tests d'intégration BFF : /bff/user sans cookie → 401 ; après login dev → 200 avec matricule ; POST /api/... sans en-tête anti-CSRF → 400/403 ; test bUnit de AuthorizeView avec le provider.
A14: 7 | B14: P2-T07 | C14: État partagé et services front de base | D14: sonnet | E14: P2-T06 | F14: NON_FAIT | G14: State/UtilisateurCourantState, State/PerimetreState (entité, niveau, chemin), Services/NotificationUiService (snackbar), Services/ChargementService (indicateur global), gestion centralisée des ApiException (message utilisateur, journal console). | H14: tests bUnit : un composant abonné à PerimetreState se rafraîchit au changement ; une ApiException 403 affiche le message « Accès refusé » via le snackbar.
A15: 8 | B15: P2-T08 | C15: Internationalisation fr / en / ar (RTL) | D15: sonnet | E15: P2-T03 | F15: NON_FAIT | G15: Resources/*.resx (fr par défaut, en, ar), sélecteur de langue persistant (cookie BFF), dir="rtl" sur <html> et règles RTL dans app.gp.css (menu latéral à droite) pour l'arabe, formats de date et de nombre selon la culture. | H15: tests bUnit : en culture ar-MA le layout est rendu avec dir="rtl" ; un libellé du menu change selon la culture ; aucun texte en dur dans Layouts/ (contrôle : test qui échoue si une chaîne littérale française apparaît dans un .razor du layout).
A16: 9 | B16: P2-T09 | C16: Pages système | D16: haiku | E16: P2-T08 | F16: NON_FAIT | G16: pages Accueil (placeholder du tableau de bord), 404, Accès refusé, Erreur inattendue (avec identifiant de corrélation), Chargement initial. | H16: tests bUnit : chaque page se rend sans exception et contient son titre traduit.

Sheet P3
A1: P3 · Conteneurisation et intégration continue GitHub Actions
A2: Objectif : images Docker, environnement local complet par docker compose, intégration continue GitHub Actions sur le dépôt hajar-hamid-coder/gprojet. Livrable : docker compose up fonctionnel et .github/workflows/ci.yml. ⚠️ Nécessite Docker (hypothèse H-001).
A3: Statut phase | B3: NON_DEMARREE
A4: Modèle conseillé | B4: sonnet
A5: Avancement | B5: =IF(COUNTA(B8:B200)=0,0,(COUNTIF(F8:F200,"A_VALIDER")+COUNTIF(F8:F200,"VALIDE"))/COUNTA(B8:B200))
A6: ← Retour à l'ordre d'exécution
A7: Ordre | B7: Code | C7: Tâche | D7: Modèle | E7: Dépend de | F7: Statut | G7: Explication | H7: Test de validation | I7: Retours utilisateur | J7: Hypothèses liées
A8: 1 | B8: P3-T01 | C8: Dockerfile de l'application | D8: sonnet | E8: — | F8: NON_FAIT | G8: deploy/docker/Dockerfile unique, multi-étapes, qui publie Gprojet-Backend (le front publié est servi par le backend) (sdk:10.0 → aspnet:10.0 chiseled ou alpine), utilisateur non-root, HEALTHCHECK, variables ASPNETCORE_*, pas de secret dans l'image ; .dockerignore. | H8: docker build -f deploy/docker/Dockerfile -t gprojet:test . réussit ; docker run --rm gprojet:test id -u ≠ 0 ; l'image contient le front (wwwroot/_framework) ; taille d'image affichée dans la preuve. | J8: H-001 (REPONDUE, bloquante)
A9: 2 | B9: P3-T02 | C9: docker compose de développement | D9: sonnet | E9: P3-T01 | F9: NON_FAIT | G9: deploy/docker-compose.yml : postgres:18 (volume, base vide), service migrations (bundle EF dotnet ef migrations bundle qui crée le schéma — pas les scripts SQL, pour rester aligné sur les migrations), app (image unique), profil keycloak (préparé pour P18), réseau dédié, dépendances sur la santé ; deploy/.env.example sans valeur sensible. | H9: docker compose -f deploy/docker-compose.yml up -d --wait puis curl -s http://localhost:8080/api/health → 200 et curl -s http://localhost:8080/ → HTML ; docker compose down -v propre.
A10: 3 | B10: P3-T03 | C10: Tests en CI avec PostgreSQL de service | D10: sonnet | E10: — | F10: NON_FAIT | G10: rendre les tests d'intégration indépendants de pg-test.py via la variable GP_TEST_CONNECTION (si définie : base fournie par la CI ; sinon : instance locale jetable). Fixture xUnit commune. | H10: dotnet test local (instance jetable) vert ; avec GP_TEST_CONNECTION pointant sur l'instance démarrée manuellement, les mêmes tests passent.
A11: 4 | B11: P3-T04 | C11: Workflow GitHub Actions | D11: sonnet | E11: P3-T01, P3-T03 | F11: NON_FAIT | G11: .github/workflows/ci.yml déclenché sur push et pull request : jobs build, test (service postgres:18, GP_TEST_CONNECTION, rapport de tests et couverture publiés comme artefacts), qualite (dotnet format --verify-no-changes), securite (CodeQL C#, dependency-review sur les pull requests, scan d'image Trivy), paquet (build et push de l'image vers GitHub Container Registry ghcr.io sur main et les tags, avec GITHUB_TOKEN), deploiement (workflow_dispatch + environnement protégé, préparé pour P13). Cache NuGet, versions d'actions épinglées. Vérifier que les modèles .github/ (faits en P1-T01) sont cohérents avec le workflow. | H11: python scripts/verifier-ci.py (à écrire, parse YAML) confirme les 6 jobs, leurs dépendances, le service PostgreSQL et l'absence de secret en clair ; les modèles .github/ sont présents. L'exécution réelle sur GitHub se constate après le push de l'utilisateur (signalé dans le bilan de phase). | J11: H-002 (REPONDUE)
A12: 5 | B12: P3-T05 | C12: Documentation de déploiement local | D12: haiku | E12: P3-T02, P3-T04 | F12: NON_FAIT | G12: docs/DEPLOIEMENT.md : prérequis, variables, démarrage compose, migrations, dépannage, description du workflow GitHub Actions, des secrets à créer (Settings → Secrets and variables → Actions) et de la publication d'image sur ghcr.io. | H12: le document contient les sections Prérequis, Démarrage, Variables, Pipeline, Dépannage ; chaque commande citée existe dans le dépôt.

Sheet P4
A1: P4 · Module Organisation et périmètre hiérarchique
A2: Objectif : organigramme, agents, délégations, absences, et le service de périmètre sur lequel repose toute la sécurité des données. Livrable : module Organisation complet (API + pages).
A3: Statut phase | B3: NON_DEMARREE
A4: Modèle conseillé | B4: sonnet
A5: Avancement | B5: =IF(COUNTA(B8:B200)=0,0,(COUNTIF(F8:F200,"A_VALIDER")+COUNTIF(F8:F200,"VALIDE"))/COUNTA(B8:B200))
A6: ← Retour à l'ordre d'exécution
A7: Ordre | B7: Code | C7: Tâche | D7: Modèle | E7: Dépend de | F7: Statut | G7: Explication | H7: Test de validation | I7: Retours utilisateur | J7: Hypothèses liées
A8: 1 | B8: P4-T01 | C8: Service de périmètre et rôles déduits | D8: opus | E8: — | F8: NON_FAIT | G8: PerimetreService : rôle hiérarchique déduit (directeur / chef de division / chef de service / agent) depuis l'entité dirigée et les délégations actives à la date du jour ; chemin ltree du périmètre ; IPerimetreCourant injectable ; extension IQueryable<Projet>.DansPerimetre() et équivalents Phase / Tâche / Ticket / Saisie (membre du projet inclus) ; politiques EstChef, EstDirecteur… | H8: tests unitaires et d'intégration (données de démo) : matrice de 12 cas (4 rôles × visibilité au-dessus / à côté / en dessous) ; délégation hors dates → aucun droit ; agent membre d'un projet d'un autre service → voit ce projet uniquement.
A9: 2 | B9: P4-T02 | C9: Organigramme : API | D9: sonnet | E9: P4-T01 | F9: NON_FAIT | G9: cas d'usage complets (DTO, validateurs, orchestrateur, service, repository, contrôleur) : créer / modifier / désactiver une entité, déplacer une entité (recalcul du chemin de tout le sous-arbre en une requête), nommer un responsable. Règles : service → parent division, division → parent direction ; un agent ne dirige qu'une entité. | H9: tests d'intégration : déplacement d'une division → chemins de ses services et projets portés mis à jour ; service rattaché à une direction → 400 ; double responsabilité → 409.
A10: 3 | B10: P4-T03 | C10: Agents, rattachements et compétences : API | D10: sonnet | E10: P4-T02 | F10: NON_FAIT | G10: CRUD agents ; mutation (clôture du rattachement, ouverture du nouveau, mise à jour de entite_id) ; fonction ; compétences avec niveau ; recherche paginée (nom, matricule, entité, compétence). | H10: tests : mutation → 2 rattachements dont 1 ouvert ; tentative de second rattachement ouvert → refus ; recherche par compétence renvoie les bons agents.
A11: 4 | B11: P4-T04 | C11: Délégations, absences et calendrier : API | D11: sonnet | E11: P4-T01 | F11: NON_FAIT | G11: délégations (période, droits, entité ; seul le responsable de l'entité délègue), absences (types, demi-journée), jours fériés ; service CalendrierService.JoursOuvres(agent, période) utilisé plus tard par le CPM et le plan de charge. | H11: tests : délégation active → le délégataire obtient PeutCreerProjet ; JoursOuvres exclut week-ends, fériés et absences (cas avec demi-journée = 0,5).
A12: 5 | B12: P4-T05 | C12: Pages organigramme | D12: sonnet | E12: P4-T02 | F12: NON_FAIT | G12: arbre interactif (composant maison ArbreOrganisation au style de la charte) avec responsable et effectif, fiche entité (membres, projets portés), formulaires création / déplacement / nomination ; écrans selon la charte HCP (design/charte-hcp/README.md). | H12: tests bUnit : l'arbre affiche 3 niveaux à partir de données simulées ; le formulaire refuse un parent incohérent (message de validation partagé) ; les actions sont masquées pour un agent.
A13: 6 | B13: P4-T06 | C13: Pages agents | D13: sonnet | E13: P4-T03 | F13: NON_FAIT | G13: liste filtrable et paginée, fiche agent (rattachements, compétences, absences, projets), dialogue de mutation, édition des compétences. | H13: tests bUnit : filtre par entité ; dialogue de mutation → appel du service avec les bons paramètres ; affichage de l'historique des rattachements.
A14: 7 | B14: P4-T07 | C14: Pages délégations, absences et calendrier | D14: sonnet | E14: P4-T04 | F14: NON_FAIT | G14: gestion des délégations par le chef (avec bandeau « vous agissez par délégation de … »), saisie des absences, calendrier des jours fériés (admin). | H14: tests bUnit : le bandeau de délégation apparaît quand l'utilisateur agit par délégation ; validation des dates (fin ≥ début).
A15: 8 | B15: P4-T08 | C15: Documentation fonctionnelle du module | D15: haiku | E15: P4-T05, P4-T06, P4-T07 | F15: NON_FAIT | G15: docs/modules/organisation.md : règles métier, rôles et droits, endpoints (lien OpenAPI), écrans. | H15: le document liste chaque endpoint du module (comparaison automatique avec /openapi/v1.json via un petit script ou test).

Sheet P5
A1: P5 · Projets et affectation en cascade
A2: Objectif : création réservée aux chefs, cascade Directeur → Division → Service → Personnel, portefeuille filtré. Livrable : module Projets complet et étanche entre périmètres.
A3: Statut phase | B3: NON_DEMARREE
A4: Modèle conseillé | B4: opus
A5: Avancement | B5: =IF(COUNTA(B8:B200)=0,0,(COUNTIF(F8:F200,"A_VALIDER")+COUNTIF(F8:F200,"VALIDE"))/COUNTA(B8:B200))
A6: ← Retour à l'ordre d'exécution
A7: Ordre | B7: Code | C7: Tâche | D7: Modèle | E7: Dépend de | F7: Statut | G7: Explication | H7: Test de validation | I7: Retours utilisateur | J7: Hypothèses liées
A8: 1 | B8: P5-T01 | C8: Référentiels : types de projet et modèles de phases | D8: sonnet | E8: — | F8: NON_FAIT | G8: API + pages d'administration des types de projet et de leurs modèles de phases (ordre, critères, mode d'enchaînement). | H8: tests : réordonnancement des modèles de phases sans trou ni doublon ; suppression d'un type utilisé → 409.
A9: 2 | B9: P5-T02 | C9: Création de projet | D9: opus | E9: P5-T01 | F9: NON_FAIT | G9: réservée aux chefs et délégataires ; code PRJ-AAAA-NNNN sans collision en concurrence (séquence annuelle) ; entité créatrice, chemin initial ; instanciation des phases depuis le modèle du type ; statut BROUILLON → EN_AFFECTATION (direction / division) ou EN_COURS (service). | H9: tests : un agent → 403 ; un chef de service → projet EN_COURS porté par son service ; 20 créations parallèles → 20 codes distincts ; les phases du modèle DEV sont créées (7).
A10: 3 | B10: P5-T03 | C10: Affectation en cascade | D10: opus | E10: P5-T02 | F10: NON_FAIT | G10: affecter (cible = enfant direct de la source), accepter (met à jour entité porteuse + chemin), renvoyer (motif obligatoire, revient à l'émetteur), réaffecter, annuler ; chaîne precedente_id ; une seule affectation active ; événements de domaine pour notifications (consommés en P9) ; historique. | H10: tests couvrant chaque transition et chaque refus (cible non enfant, double affectation, renvoi sans motif, acteur hors périmètre) ; scénario complet directeur → division → service → acceptation : chemin final = chemin du service.
A11: 4 | B11: P5-T04 | C11: Équipe projet | D11: sonnet | E11: P5-T03 | F11: NON_FAIT | G11: le chef du service porteur ajoute / retire des membres (agents de son service, prestataires et observateurs autorisés), quotas, désignation du chef de projet. | H11: tests : agent d'un autre service → refus ; somme des quotas d'un agent sur ses projets > 100 % → avertissement renvoyé (pas de blocage) ; chef de projet obligatoirement membre.
A12: 5 | B12: P5-T05 | C12: Jalons et registre RAID | D12: sonnet | E12: P5-T02 | F12: NON_FAIT | G12: CRUD jalons (lien phase optionnel, retard calculé) et éléments RAID (criticité, responsable, échéance, statut). | H12: tests : un risque sans probabilité → 400 ; jalon dépassé non atteint → statut EN_RETARD calculé.
A13: 6 | B13: P5-T06 | C13: Politiques d'autorisation et tests anti-fuite | D13: opus | E13: P5-T03, P5-T04 | F13: NON_FAIT | G13: politiques PeutCreerProjet, PeutAffecterDivision, PeutAffecterService, PeutGererEquipe, PeutVoirProjet appliquées à tous les contrôleurs Projets ; un projet hors périmètre renvoie 404 (pas 403, pour ne pas révéler son existence). | H13: suite de tests d'intégration paramétrée parcourant tous les endpoints Projets avec 4 profils : aucun accès hors périmètre (404), aucune liste ne contient de projet hors périmètre.
A14: 7 | B14: P5-T07 | C14: Pages portefeuille et création | D14: sonnet | E14: P5-T06 | F14: NON_FAIT | G14: portefeuille (grille filtrable : statut, type, priorité, météo, entité), assistant de création en étapes, fiche projet à onglets (synthèse, phases, équipe, jalons, RAID, historique). | H14: tests bUnit : le bouton « Nouveau projet » est absent pour un agent ; l'assistant valide chaque étape avant la suivante.
A15: 8 | B15: P5-T08 | C15: Pages d'affectation | D15: sonnet | E15: P5-T07 | F15: NON_FAIT | G15: file « Projets à affecter » par chef, dialogues affecter / accepter / renvoyer, frise de la chaîne d'affectation. | H15: tests bUnit : le renvoi exige un motif ; la frise affiche les étapes dans l'ordre chronologique.
A16: 9 | B16: P5-T09 | C16: Pages équipe, jalons, RAID | D16: sonnet | E16: P5-T07 | F16: NON_FAIT | G16: onglets de la fiche projet : gestion de l'équipe, jalons, matrice des risques (probabilité × impact). | H16: tests bUnit : la matrice place un risque P4×I5 dans la bonne cellule ; seuls les membres du service sont proposés dans l'ajout d'équipe.
A17: 10 | B17: P5-T10 | C17: Tâches planifiées et alerte de non-affectation | D17: sonnet | E17: P5-T03 | F17: NON_FAIT | G17: infrastructure de jobs (Quartz.NET, persistance PostgreSQL) dans Infrastructure/ ; job quotidien : projet en attente d'affectation au-delà de alerte.delai_affectation_jours → événement d'alerte au chef concerné. | H17: test avec IHorloge simulée : projet affecté il y a 6 jours (seuil 5) → 1 alerte ; 4 jours → 0.

Sheet P6
A1: P6 · Planification et ordonnancement
A2: Objectif : phases, tâches, tickets, workflows, dépendances, chemin critique. Livrable : planification complète avec Gantt et Kanban.
A3: Statut phase | B3: NON_DEMARREE
A4: Modèle conseillé | B4: opus
A5: Avancement | B5: =IF(COUNTA(B8:B200)=0,0,(COUNTIF(F8:F200,"A_VALIDER")+COUNTIF(F8:F200,"VALIDE"))/COUNTA(B8:B200))
A6: ← Retour à l'ordre d'exécution
A7: Ordre | B7: Code | C7: Tâche | D7: Modèle | E7: Dépend de | F7: Statut | G7: Explication | H7: Test de validation | I7: Retours utilisateur | J7: Hypothèses liées
A8: 1 | B8: P6-T01 | C8: Workflows configurables | D8: sonnet | E8: — | F8: NON_FAIT | G8: administration des workflows (statuts, catégories, couleurs, statut initial, transitions et rôles autorisés) ; service WorkflowService.PeutTransiter(element, vers, utilisateur). | H8: tests : transition non déclarée → refus ; transition réservée CHEF_PROJET refusée à un membre ; un workflow sans statut TERMINE est invalide.
A9: 2 | B9: P6-T02 | C9: Phases : gestion et ordre | D9: sonnet | E9: P6-T01 | F9: NON_FAIT | G9: CRUD phases, réordonnancement transactionnel sans trou, mode d'enchaînement, critères, livrables. | H9: tests : déplacer la phase 4 en position 2 → ordres 1..n continus ; mode CHEVAUCHEMENT sans pourcentage → 400.
A10: 3 | B10: P6-T03 | C10: Validation de fin de phase (gate) | D10: opus | E10: P6-T02 | F10: NON_FAIT | G10: soumission d'une phase, circuit de validation multi-niveaux (chef de service puis chef de division selon paramétrage), rejet motivé → nouveau tour, règle de démarrage de N+1 selon le mode d'enchaînement. | H10: tests : N+1 ne démarre pas tant que N n'est pas validée (mode séquentiel) ; démarre à 60 % si chevauchement à 50 % ; rejet → tour 2 sans perdre le tour 1.
A11: 4 | B11: P6-T04 | C11: Tâches : gestion, WBS, estimation | D11: sonnet | E11: P6-T02 | F11: NON_FAIT | G11: CRUD tâches, code WBS recalculé, ordre, mode d'exécution, responsable (membre du projet), estimation à trois points (PERT : (O + 4M + P) / 6), récurrence. | H11: tests : WBS « 2.3 » après déplacement ; estimation O=4, M=6, P=14 → 7 h ; responsable non membre → 400.
A12: 5 | B12: P6-T05 | C12: Dépendances, cycles et contrôle de démarrage | D12: opus | E12: P6-T04 | F12: NON_FAIT | G12: dépendances FD / DD / FF / DF avec délai ; détection de cycle (parcours en profondeur sur le graphe du projet) ; démarrage d'une tâche : mode BLOQUANT → refus si prédécesseur non terminé ; mode SOUPLE → dérogation justifiée obligatoire. | H12: tests : A→B→C puis C→A → refus « cycle » ; démarrer B avant A en mode bloquant → refus ; en mode souple sans justification → 400, avec → OK et dérogation enregistrée.
A13: 6 | B13: P6-T06 | C13: Moteur de chemin critique (CPM) | D13: opus | E13: P6-T05 | F13: NON_FAIT | G13: passes avant et arrière sur jours ouvrés (calendrier, fériés, absences du responsable, capacité), 4 types de liens et délais ; dates prévues, marges totale et libre, est_critique ; recalcul en cascade lors d'un glissement + alerte au chef de projet. | H13: tests sur 3 réseaux de référence avec résultats calculés à la main (dont un manuel de gestion de projet) : dates, marges et chemin critique exacts ; glissement de 3 jours d'une tâche critique → date de fin projet +3 jours ouvrés.
A14: 7 | B14: P6-T07 | C14: Tickets | D14: sonnet | E14: P6-T01, P6-T04 | F14: NON_FAIT | G14: CRUD tickets, numérotation atomique (prochain_numero_ticket), types et workflows, rang, liens, tickets bloquants empêchant la clôture de la tâche. | H14: tests : 50 créations parallèles → numéros 1..50 sans trou ni doublon ; clôturer une tâche avec un ticket bloquant ouvert → 409.
A15: 8 | B15: P6-T08 | C15: Remontée d'avancement et de charge | D15: sonnet | E15: P6-T07 | F15: NON_FAIT | G15: recalcul des caches ticket → tâche → phase → projet (charge estimée, reste à faire, avancement) à chaque modification, dans la même transaction. | H15: tests : passer un ticket en catégorie TERMINE met à jour l'avancement de la tâche, de la phase et du projet avec les valeurs attendues.
A16: 9 | B16: P6-T09 | C16: Baselines | D16: sonnet | E16: P6-T06 | F16: NON_FAIT | G16: figer le planning (photo des dates et charges), comparer planifié / baseline / réel, écarts par tâche et par phase. | H16: tests : après glissement, la comparaison montre l'écart exact par tâche ; deux baselines coexistent.
A17: 10 | B17: P6-T10 | C17: Pages liste, Kanban et fiches | D17: sonnet | E17: P6-T08 | F17: NON_FAIT | G17: vue liste hiérarchique (phase > tâche > ticket), Kanban des tickets par statut avec glisser-déposer respectant les transitions, fiches tâche et ticket, « Ma prochaine tâche » et « Mes tickets ». | H17: tests bUnit : un dépôt vers une colonne non autorisée est refusé visuellement et non envoyé ; « Ma prochaine tâche » affiche la tâche prête la plus prioritaire.
A18: 11 | B18: P6-T11 | C18: Gantt et réseau PERT | D18: opus | E18: P6-T06, P6-T10 | F18: NON_FAIT | G18: composant Gantt (bibliothèque JS sous licence libre via JS Interop, choix consigné en hypothèse) : barres, dépendances, jalons, chemin critique en surbrillance, déplacement → recalcul ; vue PERT (graphe) ; accessibilité clavier minimale et alternative tabulaire. | H18: test bUnit de l'enveloppe (données transmises au module JS) ; test d'intégration : le déplacement envoie la bonne requête et le recalcul revient ; vérification manuelle décrite dans la preuve (capture). | J18: H-005 (OUVERTE)
A19: 12 | B19: P6-T12 | C19: Documentation du module | D19: haiku | E19: P6-T11 | F19: NON_FAIT | G19: docs/modules/planification.md : règles d'ordonnancement, modes, CPM (formules), workflows par défaut. | H19: le document contient les sections Ordonnancement, CPM, Workflows, Écrans et un exemple chiffré.

Sheet P7
A1: P7 · Coût en temps
A2: Objectif : saisie, validation hiérarchique, prévu / consommé / reste à faire, plan de charge. Livrable : module Temps complet.
A3: Statut phase | B3: NON_DEMARREE
A4: Modèle conseillé | B4: sonnet
A5: Avancement | B5: =IF(COUNTA(B8:B200)=0,0,(COUNTIF(F8:F200,"A_VALIDER")+COUNTIF(F8:F200,"VALIDE"))/COUNTA(B8:B200))
A6: ← Retour à l'ordre d'exécution
A7: Ordre | B7: Code | C7: Tâche | D7: Modèle | E7: Dépend de | F7: Statut | G7: Explication | H7: Test de validation | I7: Retours utilisateur | J7: Hypothèses liées
A8: 1 | B8: P7-T01 | C8: Référentiels et paramètres du temps | D8: haiku | E8: — | F8: NON_FAIT | G8: administration des catégories d'activité (projet / hors projet) et des paramètres (heures par jour, seuils). | H8: tests : désactiver une catégorie utilisée la masque à la saisie sans casser l'historique.
A9: 2 | B9: P7-T02 | C9: Feuilles de temps et saisies | D9: sonnet | E9: P7-T01 | F9: NON_FAIT | G9: feuille hebdomadaire (créée à la demande), saisies avec règles : catégorie projet ⇒ tâche obligatoire, ticket appartenant à la tâche, total ≤ 24 h par jour, agent membre du projet, lecture seule si feuille validée ou verrouillée. | H9: tests pour chaque règle (cas nominal + refus) ; saisie hors projet acceptée sans tâche.
A10: 3 | B10: P7-T03 | C10: Chronomètre | D10: sonnet | E10: P7-T02 | F10: NON_FAIT | G10: démarrer / arrêter un chronomètre depuis un ticket (un seul actif par agent), conversion en saisie arrondie au quart d'heure. | H10: tests : 1 h 08 → 1,25 h ; second chronomètre → arrêt automatique du premier.
A11: 4 | B11: P7-T04 | C11: Circuit de validation des temps | D11: opus | E11: P7-T02 | F11: NON_FAIT | G11: soumettre, valider / rejeter (motif) par le chef du service de rattachement à la date de la semaine (historique des rattachements, délégations), verrouillage de période, consolidation par le chef de division. | H11: tests : agent muté en cours de mois → la semaine antérieure est validée par l'ancien chef ; rejet sans motif → 400 ; période verrouillée → modification refusée.
A12: 5 | B12: P7-T05 | C12: Prévu, consommé, reste à faire et alertes | D12: sonnet | E12: P7-T04 | F12: NON_FAIT | G12: agrégation des temps validés en jours-homme par tâche / phase / projet, écarts (jours, %), reprévision de la date de fin selon la vélocité réelle, job d'alerte au-delà du seuil de charge consommée. | H12: tests chiffrés : estimé 10 j, consommé 8,5 j → 85 % → alerte (seuil 80) ; reprévision conforme à la formule documentée.
A13: 6 | B13: P7-T06 | C13: Plan de charge et taux d'occupation | D13: sonnet | E13: P7-T05 | F13: NON_FAIT | G13: charge affectée vs capacité par agent, service, division, direction (jours ouvrés, absences, quotas) ; taux d'occupation incluant le hors-projet ; surcharge / sous-charge. | H13: tests chiffrés sur les données de démo : taux d'occupation d'un service = valeur calculée à la main dans le test.
A14: 7 | B14: P7-T07 | C14: Pages saisie, chronomètre et validation | D14: sonnet | E14: P7-T04 | F14: NON_FAIT | G14: grille hebdomadaire (lignes tâches / tickets, colonnes jours, totaux), widget chronomètre dans la barre d'application, file de validation des chefs. | H14: tests bUnit : total journalier > 24 h signalé avant envoi ; la file de validation n'affiche que les agents du périmètre.
A15: 8 | B15: P7-T08 | C15: Page plan de charge | D15: sonnet | E15: P7-T06 | F15: NON_FAIT | G15: carte de chaleur agents × semaines (couleurs de surcharge du thème), filtres par entité et compétence. | H15: tests bUnit : une cellule à 120 % porte la classe « surcharge » ; filtre par compétence.

Sheet P8
A1: P8 · Reporting par niveau hiérarchique
A2: Objectif : tableaux de bord Directeur / Division / Service / Agent avec drill-down et exports. Livrable : reporting complet, rapide et étanche.
A3: Statut phase | B3: NON_DEMARREE
A4: Modèle conseillé | B4: sonnet
A5: Avancement | B5: =IF(COUNTA(B8:B200)=0,0,(COUNTIF(F8:F200,"A_VALIDER")+COUNTIF(F8:F200,"VALIDE"))/COUNTA(B8:B200))
A6: ← Retour à l'ordre d'exécution
A7: Ordre | B7: Code | C7: Tâche | D7: Modèle | E7: Dépend de | F7: Statut | G7: Explication | H7: Test de validation | I7: Retours utilisateur | J7: Hypothèses liées
A8: 1 | B8: P8-T01 | C8: Requêtes de reporting | D8: opus | E8: — | F8: NON_FAIT | G8: requêtes de lecture dédiées (projections ou SQL) filtrées par périmètre : synthèse portefeuille (statut, type, priorité, météo), comparatifs divisions / services, charges et écarts, retards, affectations en attente et délais d'affectation, validations en attente, jalons à 30/60/90 jours, risques et vulnérabilités critiques. | H8: tests chiffrés sur un jeu de données dédié (valeurs attendues écrites dans le test) ; un chef de division ne reçoit aucune ligne d'une autre division ; chaque requête < 300 ms sur ce jeu (mesure dans le test).
A9: 2 | B9: P8-T02 | C9: Tableau de bord Directeur | D9: sonnet | E9: P8-T01 | F9: NON_FAIT | G9: indicateurs de synthèse, comparatif des divisions (graphiques), projets non affectés, retards, validations en attente, jalons, risques ; cartes .stat-card, graphiques Chart.js aux couleurs de la charte, ergonomie via ui-ux-pro-max. | H9: tests bUnit : chaque widget gère les états vide / chargement / erreur ; les valeurs affichées correspondent au DTO fourni.
A10: 3 | B10: P8-T03 | C10: Tableau de bord Chef de division | D10: sonnet | E10: P8-T01 | F10: NON_FAIT | G10: mêmes indicateurs sur la division, comparatif des services, projets à affecter, charge par service. | H10: tests bUnit analogues à P8-T02.
A11: 4 | B11: P8-T04 | C11: Tableau de bord Chef de service | D11: sonnet | E11: P8-T01 | F11: NON_FAIT | G11: projets du service, équipes à constituer, charge par agent, feuilles à valider, tâches bloquées et critiques, tickets en retard. | H11: tests bUnit analogues à P8-T02.
A12: 5 | B12: P8-T05 | C12: Tableau de bord Agent | D12: sonnet | E12: P8-T01 | F12: NON_FAIT | G12: ma prochaine tâche, mes tickets par priorité et ordre, temps de la semaine, échéances. | H12: tests bUnit analogues à P8-T02.
A13: 6 | B13: P8-T06 | C13: Navigation de drill-down | D13: sonnet | E13: P8-T02, P8-T03, P8-T04 | F13: NON_FAIT | G13: composant fil d'Ariane Direction → Division → Service → Projet → Phase → Tâche → Ticket → Agent, conservation des filtres dans l'URL, retour arrière cohérent. | H13: tests bUnit : cliquer sur une division filtre le tableau de bord et ajoute un niveau au fil d'Ariane ; l'URL contient les filtres.
A14: 7 | B14: P8-T07 | C14: Exports Excel et PDF | D14: sonnet | E14: P8-T01 | F14: NON_FAIT | G14: export Excel (bibliothèque libre) et PDF au format officiel (en-tête, logo de l'entité) des rapports standard ; choix des bibliothèques et licences consigné en hypothèse. | H14: tests : le fichier Excel contient les colonnes et le nombre de lignes attendus ; le PDF est lisible (extraction du texte contient le titre du rapport). | J14: H-006 (OUVERTE) H-007 (OUVERTE)
A15: 8 | B15: P8-T08 | C15: Rapports planifiés par e-mail | D15: sonnet | E15: P8-T07 | F15: NON_FAIT | G15: job hebdomadaire / mensuel envoyant à chaque chef le rapport de son périmètre ; envoi SMTP via Infrastructure/ (en développement : dépôt dans un dossier de fichiers .eml). | H15: test : exécution du job en développement → un .eml par chef, contenant uniquement les projets de son périmètre.

Sheet P9
A1: P9 · Collaboration et services transverses
A2: Objectif : commentaires, pièces jointes, notifications temps réel, historique consultable. Livrable : collaboration sur tout élément.
A3: Statut phase | B3: NON_DEMARREE
A4: Modèle conseillé | B4: sonnet
A5: Avancement | B5: =IF(COUNTA(B8:B200)=0,0,(COUNTIF(F8:F200,"A_VALIDER")+COUNTIF(F8:F200,"VALIDE"))/COUNTA(B8:B200))
A6: ← Retour à l'ordre d'exécution
A7: Ordre | B7: Code | C7: Tâche | D7: Modèle | E7: Dépend de | F7: Statut | G7: Explication | H7: Test de validation | I7: Retours utilisateur | J7: Hypothèses liées
A8: 1 | B8: P9-T01 | C8: Commentaires et mentions | D8: sonnet | E8: — | F8: NON_FAIT | G8: commentaires polymorphes (projet, phase, tâche, ticket, diagramme…), fils de discussion, @mention d'un agent du projet, édition marquée, droits selon le périmètre de l'élément commenté. | H8: tests : commenter un ticket hors périmètre → 404 ; une mention crée un événement de notification ; un fil de 3 niveaux est restitué dans l'ordre.
A9: 2 | B9: P9-T02 | C9: Pièces jointes | D9: sonnet | E9: — | F9: NON_FAIT | G9: téléversement en flux (taille max et types autorisés paramétrés), stockage disque configurable hors racine web, empreinte SHA-256, téléchargement contrôlé par le périmètre ; point d'extension pour un antivirus (hypothèse). | H9: tests : fichier > taille max → 413 ; extension interdite → 400 ; l'empreinte stockée correspond au fichier ; téléchargement hors périmètre → 404. | J9: H-008 (OUVERTE)
A10: 3 | B10: P9-T03 | C10: Notifications temps réel | D10: sonnet | E10: P9-T01 | F10: NON_FAIT | G10: consommation des événements de domaine (affectation, mention, validation, échéance…) → notifications en base, diffusion SignalR, centre de notifications côté front, préférences par type, résumé quotidien par e-mail. | H10: test d'intégration SignalR : une affectation provoque la réception du message par le client du chef ciblé et pas par un autre ; test bUnit du compteur non lu.
A11: 4 | B11: P9-T04 | C11: Abonnements (observateurs) | D11: sonnet | E11: P9-T03 | F11: NON_FAIT | G11: nouvelle table commun.abonnement (migration + mise à jour du MLD), s'abonner / se désabonner d'un élément, notifications aux abonnés. | H11: python scripts/comparer-schema.py toujours à 0 écart après mise à jour de database/01-schema.sql ; un abonné reçoit la notification d'un changement de statut.
A12: 5 | B12: P9-T05 | C12: Historique et vérification d'intégrité | D12: sonnet | E12: — | F12: NON_FAIT | G12: frise d'historique par élément (qui, quoi, quand, avant / après), endpoint d'administration qui vérifie la chaîne d'empreintes et signale la première rupture. | H12: tests : la frise d'un ticket modifié 3 fois contient 3 entrées ; une altération SQL directe est détectée à la bonne ligne.

Sheet P10
A1: P10 · Modélisation et diagrammes
A2: Objectif : métamodèle éditable, cohérence, transformation MCD → MLD → SQL, éditeurs de diagrammes. Livrable : module Modélisation, capable de reproduire le MLD de la plateforme.
A3: Statut phase | B3: NON_DEMARREE
A4: Modèle conseillé | B4: opus
A5: Avancement | B5: =IF(COUNTA(B8:B200)=0,0,(COUNTIF(F8:F200,"A_VALIDER")+COUNTIF(F8:F200,"VALIDE"))/COUNTA(B8:B200))
A6: ← Retour à l'ordre d'exécution
A7: Ordre | B7: Code | C7: Tâche | D7: Modèle | E7: Dépend de | F7: Statut | G7: Explication | H7: Test de validation | I7: Retours utilisateur | J7: Hypothèses liées
A8: 1 | B8: P10-T01 | C8: API du métamodèle | D8: sonnet | E8: — | F8: NON_FAIT | G8: CRUD modèles (versions), modules, entités, attributs, énumérations et valeurs, associations et pattes, index, méthodes et paramètres ; validations (noms techniques snake_case, rôle obligatoire sur une association réflexive, propriétaire unique d'un attribut). | H8: tests d'intégration couvrant chaque ressource et chaque règle de validation.
